Internal Server Error: /admin/login/
Traceback (most recent call last):
  File "C:\Users\dilep\Desktop\deep\env\Lib\site-packages\django\db\models\fields\related_descriptors.py", line 512, in __get__
    rel_obj = self.related.get_cached_value(instance)
  File "C:\Users\dilep\Desktop\deep\env\Lib\site-packages\django\db\models\fields\mixins.py", line 37, in get_cached_value
    return instance._state.fields_cache[self.cache_name]
           ~~~~~~~~~~~~~~~~~~~~~~~~~~~~^^^^^^^^^^^^^^^^^
KeyError: 'userprofile'

During handling of the above exception, another exception occurred:

Traceback (most recent call last):
  File "C:\Users\dilep\Desktop\deep\env\Lib\site-packages\django\db\backends\utils.py", line 105, in _execute
    return self.cursor.execute(sql, params)
           ~~~~~~~~~~~~~~~~~~~^^^^^^^^^^^^^
  File "C:\Users\dilep\Desktop\deep\env\Lib\site-packages\django\db\backends\mysql\base.py", line 76, in execute
    return self.cursor.execute(query, args)
           ~~~~~~~~~~~~~~~~~~~^^^^^^^^^^^^^
  File "C:\Users\dilep\Desktop\deep\env\Lib\site-packages\MySQLdb\cursors.py", line 179, in execute
    res = self._query(mogrified_query)
  File "C:\Users\dilep\Desktop\deep\env\Lib\site-packages\MySQLdb\cursors.py", line 330, in _query
    db.query(q)
    ~~~~~~~~^^^
  File "C:\Users\dilep\Desktop\deep\env\Lib\site-packages\MySQLdb\connections.py", line 280, in query
    _mysql.connection.query(self, query)
    ~~~~~~~~~~~~~~~~~~~~~~~^^^^^^^^^^^^^
MySQLdb.OperationalError: (1054, "Unknown column 'wasteapp_userprofile.total_credits' in 'field list'")

The above exception was the direct cause of the following exception:

Traceback (most recent call last):
  File "C:\Users\dilep\Desktop\deep\env\Lib\site-packages\django\core\handlers\exception.py", line 55, in inner
    response = get_response(request)
  File "C:\Users\dilep\Desktop\deep\env\Lib\site-packages\django\core\handlers\base.py", line 197, in _get_response
    response = wrapped_callback(request, *callback_args, **callback_kwargs)
  File "C:\Users\dilep\Desktop\deep\env\Lib\site-packages\django\utils\decorators.py", line 48, in _wrapper
    return bound_method(*args, **kwargs)
  File "C:\Users\dilep\Desktop\deep\env\Lib\site-packages\django\views\decorators\cache.py", line 80, in _view_wrapper
    response = view_func(request, *args, **kwargs)
  File "C:\Users\dilep\Desktop\deep\env\Lib\site-packages\django\contrib\admin\sites.py", line 444, in login
    return LoginView.as_view(**defaults)(request)
           ~~~~~~~~~~~~~~~~~~~~~~~~~~~~~^^^^^^^^^
  File "C:\Users\dilep\Desktop\deep\env\Lib\site-packages\django\views\generic\base.py", line 104, in view
    return self.dispatch(request, *args, **kwargs)
           ~~~~~~~~~~~~~^^^^^^^^^^^^^^^^^^^^^^^^^^
  File "C:\Users\dilep\Desktop\deep\env\Lib\site-packages\django\utils\decorators.py", line 48, in _wrapper
    return bound_method(*args, **kwargs)
  File "C:\Users\dilep\Desktop\deep\env\Lib\site-packages\django\utils\decorators.py", line 48, in _wrapper
    return bound_method(*args, **kwargs)
  File "C:\Users\dilep\Desktop\deep\env\Lib\site-packages\django\views\decorators\debug.py", line 143, in sensitive_post_parameters_wrapper
    return view(request, *args, **kwargs)
  File "C:\Users\dilep\Desktop\deep\env\Lib\site-packages\django\utils\decorators.py", line 48, in _wrapper
    return bound_method(*args, **kwargs)
  File "C:\Users\dilep\Desktop\deep\env\Lib\site-packages\django\utils\decorators.py", line 188, in _view_wrapper
    result = _process_exception(request, e)
  File "C:\Users\dilep\Desktop\deep\env\Lib\site-packages\django\utils\decorators.py", line 186, in _view_wrapper
    response = view_func(request, *args, **kwargs)
  File "C:\Users\dilep\Desktop\deep\env\Lib\site-packages\django\utils\decorators.py", line 48, in _wrapper
    return bound_method(*args, **kwargs)
  File "C:\Users\dilep\Desktop\deep\env\Lib\site-packages\django\views\decorators\cache.py", line 80, in _view_wrapper
    response = view_func(request, *args, **kwargs)
  File "C:\Users\dilep\Desktop\deep\env\Lib\site-packages\django\contrib\auth\views.py", line 89, in dispatch
    return super().dispatch(request, *args, **kwargs)
           ~~~~~~~~~~~~~~~~^^^^^^^^^^^^^^^^^^^^^^^^^^
  File "C:\Users\dilep\Desktop\deep\env\Lib\site-packages\django\views\generic\base.py", line 143, in dispatch
    return handler(request, *args, **kwargs)
  File "C:\Users\dilep\Desktop\deep\env\Lib\site-packages\django\views\generic\edit.py", line 151, in post
    return self.form_valid(form)
           ~~~~~~~~~~~~~~~^^^^^^
  File "C:\Users\dilep\Desktop\deep\env\Lib\site-packages\django\contrib\auth\views.py", line 108, in form_valid
    auth_login(self.request, form.get_user())
    ~~~~~~~~~~^^^^^^^^^^^^^^^^^^^^^^^^^^^^^^^
  File "C:\Users\dilep\Desktop\deep\env\Lib\site-packages\django\contrib\auth\__init__.py", line 152, in login
    user_logged_in.send(sender=user.__class__, request=request, user=user)
    ~~~~~~~~~~~~~~~~~~~^^^^^^^^^^^^^^^^^^^^^^^^^^^^^^^^^^^^^^^^^^^^^^^^^^^
  File "C:\Users\dilep\Desktop\deep\env\Lib\site-packages\django\dispatch\dispatcher.py", line 189, in send
    response = receiver(signal=self, sender=sender, **named)
  File "C:\Users\dilep\Desktop\deep\env\Lib\site-packages\django\contrib\auth\models.py", line 24, in update_last_login
    user.save(update_fields=["last_login"])
    ~~~~~~~~~^^^^^^^^^^^^^^^^^^^^^^^^^^^^^^
  File "C:\Users\dilep\Desktop\deep\env\Lib\site-packages\django\contrib\auth\base_user.py", line 62, in save
    super().save(*args, **kwargs)
    ~~~~~~~~~~~~^^^^^^^^^^^^^^^^^
  File "C:\Users\dilep\Desktop\deep\env\Lib\site-packages\django\db\models\base.py", line 892, in save
    self.save_base(
    ~~~~~~~~~~~~~~^
        using=using,
        ^^^^^^^^^^^^
    ...<2 lines>...
        update_fields=update_fields,
        ^^^^^^^^^^^^^^^^^^^^^^^^^^^^
    )
    ^
  File "C:\Users\dilep\Desktop\deep\env\Lib\site-packages\django\db\models\base.py", line 1013, in save_base
    post_save.send(
    ~~~~~~~~~~~~~~^
        sender=origin,
        ^^^^^^^^^^^^^^
    ...<4 lines>...
        using=using,
        ^^^^^^^^^^^^
    )
    ^
  File "C:\Users\dilep\Desktop\deep\env\Lib\site-packages\django\dispatch\dispatcher.py", line 189, in send
    response = receiver(signal=self, sender=sender, **named)
  File "C:\Users\dilep\Desktop\deep\wasteapp\models.py", line 23, in save_user_profile
    instance.userprofile.save()
    ^^^^^^^^^^^^^^^^^^^^
  File "C:\Users\dilep\Desktop\deep\env\Lib\site-packages\django\db\models\fields\related_descriptors.py", line 520, in __get__
    rel_obj = self.get_queryset(instance=instance).get(**filter_args)
  File "C:\Users\dilep\Desktop\deep\env\Lib\site-packages\django\db\models\query.py", line 645, in get
    num = len(clone)
  File "C:\Users\dilep\Desktop\deep\env\Lib\site-packages\django\db\models\query.py", line 382, in __len__
    self._fetch_all()
    ~~~~~~~~~~~~~~~^^
  File "C:\Users\dilep\Desktop\deep\env\Lib\site-packages\django\db\models\query.py", line 1928, in _fetch_all
    self._result_cache = list(self._iterable_class(self))
                         ~~~~^^^^^^^^^^^^^^^^^^^^^^^^^^^^
  File "C:\Users\dilep\Desktop\deep\env\Lib\site-packages\django\db\models\query.py", line 91, in __iter__
    results = compiler.execute_sql(
        chunked_fetch=self.chunked_fetch, chunk_size=self.chunk_size
    )
  File "C:\Users\dilep\Desktop\deep\env\Lib\site-packages\django\db\models\sql\compiler.py", line 1574, in execute_sql
    cursor.execute(sql, params)
    ~~~~~~~~~~~~~~^^^^^^^^^^^^^
  File "C:\Users\dilep\Desktop\deep\env\Lib\site-packages\django\db\backends\utils.py", line 122, in execute
    return super().execute(sql, params)
           ~~~~~~~~~~~~~~~^^^^^^^^^^^^^
  File "C:\Users\dilep\Desktop\deep\env\Lib\site-packages\django\db\backends\utils.py", line 79, in execute
    return self._execute_with_wrappers(
           ~~~~~~~~~~~~~~~~~~~~~~~~~~~^
        sql, params, many=False, executor=self._execute
        ^^^^^^^^^^^^^^^^^^^^^^^^^^^^^^^^^^^^^^^^^^^^^^^
    )
    ^
  File "C:\Users\dilep\Desktop\deep\env\Lib\site-packages\django\db\backends\utils.py", line 92, in _execute_with_wrappers
    return executor(sql, params, many, context)
  File "C:\Users\dilep\Desktop\deep\env\Lib\site-packages\django\db\backends\utils.py", line 100, in _execute
    with self.db.wrap_database_errors:
         ^^^^^^^^^^^^^^^^^^^^^^^^^^^^
  File "C:\Users\dilep\Desktop\deep\env\Lib\site-packages\django\db\utils.py", line 91, in __exit__
    raise dj_exc_value.with_traceback(traceback) from exc_value
  File "C:\Users\dilep\Desktop\deep\env\Lib\site-packages\django\db\backends\utils.py", line 105, in _execute
    return self.cursor.execute(sql, params)
           ~~~~~~~~~~~~~~~~~~~^^^^^^^^^^^^^
  File "C:\Users\dilep\Desktop\deep\env\Lib\site-packages\django\db\backends\mysql\base.py", line 76, in execute
    return self.cursor.execute(query, args)
           ~~~~~~~~~~~~~~~~~~~^^^^^^^^^^^^^
  File "C:\Users\dilep\Desktop\deep\env\Lib\site-packages\MySQLdb\cursors.py", line 179, in execute
    res = self._query(mogrified_query)
  File "C:\Users\dilep\Desktop\deep\env\Lib\site-packages\MySQLdb\cursors.py", line 330, in _query
    db.query(q)
    ~~~~~~~~^^^
  File "C:\Users\dilep\Desktop\deep\env\Lib\site-packages\MySQLdb\connections.py", line 280, in query
    _mysql.connection.query(self, query)
    ~~~~~~~~~~~~~~~~~~~~~~~^^^^^^^^^^^^^
django.db.utils.OperationalError: (1054, "Unknown column 'wasteapp_userprofile.total_credits' in 'field list'")
"POST /admin/login/?next=/admin/ HTTP/1.1" 500 292725
Internal Server Error: /admin/login/
Traceback (most recent call last):
  File "C:\Users\dilep\Desktop\deep\env\Lib\site-packages\django\core\handlers\exception.py", line 55, in inner
    response = get_response(request)
  File "C:\Users\dilep\Desktop\deep\env\Lib\site-packages\django\core\handlers\base.py", line 197, in _get_response
    response = wrapped_callback(request, *callback_args, **callback_kwargs)
  File "C:\Users\dilep\Desktop\deep\env\Lib\site-packages\django\utils\decorators.py", line 48, in _wrapper
    return bound_method(*args, **kwargs)
  File "C:\Users\dilep\Desktop\deep\env\Lib\site-packages\django\views\decorators\cache.py", line 80, in _view_wrapper
    response = view_func(request, *args, **kwargs)
  File "C:\Users\dilep\Desktop\deep\env\Lib\site-packages\django\contrib\admin\sites.py", line 444, in login
    return LoginView.as_view(**defaults)(request)
           ~~~~~~~~~~~~~~~~~~~~~~~~~~~~~^^^^^^^^^
  File "C:\Users\dilep\Desktop\deep\env\Lib\site-packages\django\views\generic\base.py", line 104, in view
    return self.dispatch(request, *args, **kwargs)
           ~~~~~~~~~~~~~^^^^^^^^^^^^^^^^^^^^^^^^^^
  File "C:\Users\dilep\Desktop\deep\env\Lib\site-packages\django\utils\decorators.py", line 48, in _wrapper
    return bound_method(*args, **kwargs)
  File "C:\Users\dilep\Desktop\deep\env\Lib\site-packages\django\utils\decorators.py", line 48, in _wrapper
    return bound_method(*args, **kwargs)
  File "C:\Users\dilep\Desktop\deep\env\Lib\site-packages\django\views\decorators\debug.py", line 143, in sensitive_post_parameters_wrapper
    return view(request, *args, **kwargs)
  File "C:\Users\dilep\Desktop\deep\env\Lib\site-packages\django\utils\decorators.py", line 48, in _wrapper
    return bound_method(*args, **kwargs)
  File "C:\Users\dilep\Desktop\deep\env\Lib\site-packages\django\utils\decorators.py", line 188, in _view_wrapper
    result = _process_exception(request, e)
  File "C:\Users\dilep\Desktop\deep\env\Lib\site-packages\django\utils\decorators.py", line 186, in _view_wrapper
    response = view_func(request, *args, **kwargs)
  File "C:\Users\dilep\Desktop\deep\env\Lib\site-packages\django\utils\decorators.py", line 48, in _wrapper
    return bound_method(*args, **kwargs)
  File "C:\Users\dilep\Desktop\deep\env\Lib\site-packages\django\views\decorators\cache.py", line 80, in _view_wrapper
    response = view_func(request, *args, **kwargs)
  File "C:\Users\dilep\Desktop\deep\env\Lib\site-packages\django\contrib\auth\views.py", line 89, in dispatch
    return super().dispatch(request, *args, **kwargs)
           ~~~~~~~~~~~~~~~~^^^^^^^^^^^^^^^^^^^^^^^^^^
  File "C:\Users\dilep\Desktop\deep\env\Lib\site-packages\django\views\generic\base.py", line 143, in dispatch
    return handler(request, *args, **kwargs)
  File "C:\Users\dilep\Desktop\deep\env\Lib\site-packages\django\views\generic\edit.py", line 151, in post
    return self.form_valid(form)
           ~~~~~~~~~~~~~~~^^^^^^
  File "C:\Users\dilep\Desktop\deep\env\Lib\site-packages\django\contrib\auth\views.py", line 108, in form_valid
    auth_login(self.request, form.get_user())
    ~~~~~~~~~~^^^^^^^^^^^^^^^^^^^^^^^^^^^^^^^
  File "C:\Users\dilep\Desktop\deep\env\Lib\site-packages\django\contrib\auth\__init__.py", line 152, in login
    user_logged_in.send(sender=user.__class__, request=request, user=user)
    ~~~~~~~~~~~~~~~~~~~^^^^^^^^^^^^^^^^^^^^^^^^^^^^^^^^^^^^^^^^^^^^^^^^^^^
  File "C:\Users\dilep\Desktop\deep\env\Lib\site-packages\django\dispatch\dispatcher.py", line 189, in send
    response = receiver(signal=self, sender=sender, **named)
  File "C:\Users\dilep\Desktop\deep\env\Lib\site-packages\django\contrib\auth\models.py", line 24, in update_last_login
    user.save(update_fields=["last_login"])
    ~~~~~~~~~^^^^^^^^^^^^^^^^^^^^^^^^^^^^^^
  File "C:\Users\dilep\Desktop\deep\env\Lib\site-packages\django\contrib\auth\base_user.py", line 62, in save
    super().save(*args, **kwargs)
    ~~~~~~~~~~~~^^^^^^^^^^^^^^^^^
  File "C:\Users\dilep\Desktop\deep\env\Lib\site-packages\django\db\models\base.py", line 892, in save
    self.save_base(
    ~~~~~~~~~~~~~~^
        using=using,
        ^^^^^^^^^^^^
    ...<2 lines>...
        update_fields=update_fields,
        ^^^^^^^^^^^^^^^^^^^^^^^^^^^^
    )
    ^
  File "C:\Users\dilep\Desktop\deep\env\Lib\site-packages\django\db\models\base.py", line 1013, in save_base
    post_save.send(
    ~~~~~~~~~~~~~~^
        sender=origin,
        ^^^^^^^^^^^^^^
    ...<4 lines>...
        using=using,
        ^^^^^^^^^^^^
    )
    ^
  File "C:\Users\dilep\Desktop\deep\env\Lib\site-packages\django\dispatch\dispatcher.py", line 189, in send
    response = receiver(signal=self, sender=sender, **named)
  File "C:\Users\dilep\Desktop\deep\wasteapp\models.py", line 23, in save_user_profile
    instance.userprofile.save()
    ^^^^^^^^^^^^^^^^^^^^
  File "C:\Users\dilep\Desktop\deep\env\Lib\site-packages\django\db\models\fields\related_descriptors.py", line 531, in __get__
    raise self.RelatedObjectDoesNotExist(
    ...<2 lines>...
    )
django.contrib.auth.models.User.userprofile.RelatedObjectDoesNotExist: User has no userprofile.
"POST /admin/login/?next=/admin/ HTTP/1.1" 500 192443
Internal Server Error: /admin/wasteapp/userprofile/
Traceback (most recent call last):
  File "C:\Users\dilep\Desktop\deep\env\Lib\site-packages\django\db\backends\utils.py", line 105, in _execute
    return self.cursor.execute(sql, params)
           ~~~~~~~~~~~~~~~~~~~^^^^^^^^^^^^^
  File "C:\Users\dilep\Desktop\deep\env\Lib\site-packages\django\db\backends\mysql\base.py", line 76, in execute
    return self.cursor.execute(query, args)
           ~~~~~~~~~~~~~~~~~~~^^^^^^^^^^^^^
  File "C:\Users\dilep\Desktop\deep\env\Lib\site-packages\MySQLdb\cursors.py", line 179, in execute
    res = self._query(mogrified_query)
  File "C:\Users\dilep\Desktop\deep\env\Lib\site-packages\MySQLdb\cursors.py", line 330, in _query
    db.query(q)
    ~~~~~~~~^^^
  File "C:\Users\dilep\Desktop\deep\env\Lib\site-packages\MySQLdb\connections.py", line 280, in query
    _mysql.connection.query(self, query)
    ~~~~~~~~~~~~~~~~~~~~~~~^^^^^^^^^^^^^
MySQLdb.OperationalError: (1054, "Unknown column 'wasteapp_userprofile.credits' in 'field list'")

The above exception was the direct cause of the following exception:

Traceback (most recent call last):
  File "C:\Users\dilep\Desktop\deep\env\Lib\site-packages\django\core\handlers\exception.py", line 55, in inner
    response = get_response(request)
  File "C:\Users\dilep\Desktop\deep\env\Lib\site-packages\django\core\handlers\base.py", line 197, in _get_response
    response = wrapped_callback(request, *callback_args, **callback_kwargs)
  File "C:\Users\dilep\Desktop\deep\env\Lib\site-packages\django\contrib\admin\options.py", line 718, in wrapper
    return self.admin_site.admin_view(view)(*args, **kwargs)
           ~~~~~~~~~~~~~~~~~~~~~~~~~~~~~~~~^^^^^^^^^^^^^^^^^
  File "C:\Users\dilep\Desktop\deep\env\Lib\site-packages\django\utils\decorators.py", line 188, in _view_wrapper
    result = _process_exception(request, e)
  File "C:\Users\dilep\Desktop\deep\env\Lib\site-packages\django\utils\decorators.py", line 186, in _view_wrapper
    response = view_func(request, *args, **kwargs)
  File "C:\Users\dilep\Desktop\deep\env\Lib\site-packages\django\views\decorators\cache.py", line 80, in _view_wrapper
    response = view_func(request, *args, **kwargs)
  File "C:\Users\dilep\Desktop\deep\env\Lib\site-packages\django\contrib\admin\sites.py", line 241, in inner
    return view(request, *args, **kwargs)
  File "C:\Users\dilep\Desktop\deep\env\Lib\site-packages\django\utils\decorators.py", line 48, in _wrapper
    return bound_method(*args, **kwargs)
  File "C:\Users\dilep\Desktop\deep\env\Lib\site-packages\django\utils\decorators.py", line 188, in _view_wrapper
    result = _process_exception(request, e)
  File "C:\Users\dilep\Desktop\deep\env\Lib\site-packages\django\utils\decorators.py", line 186, in _view_wrapper
    response = view_func(request, *args, **kwargs)
  File "C:\Users\dilep\Desktop\deep\env\Lib\site-packages\django\contrib\admin\options.py", line 2138, in changelist_view
    "selection_note": _("0 of %(cnt)s selected") % {"cnt": len(cl.result_list)},
                                                           ~~~^^^^^^^^^^^^^^^^
  File "C:\Users\dilep\Desktop\deep\env\Lib\site-packages\django\db\models\query.py", line 382, in __len__
    self._fetch_all()
    ~~~~~~~~~~~~~~~^^
  File "C:\Users\dilep\Desktop\deep\env\Lib\site-packages\django\db\models\query.py", line 1928, in _fetch_all
    self._result_cache = list(self._iterable_class(self))
                         ~~~~^^^^^^^^^^^^^^^^^^^^^^^^^^^^
  File "C:\Users\dilep\Desktop\deep\env\Lib\site-packages\django\db\models\query.py", line 91, in __iter__
    results = compiler.execute_sql(
        chunked_fetch=self.chunked_fetch, chunk_size=self.chunk_size
    )
  File "C:\Users\dilep\Desktop\deep\env\Lib\site-packages\django\db\models\sql\compiler.py", line 1574, in execute_sql
    cursor.execute(sql, params)
    ~~~~~~~~~~~~~~^^^^^^^^^^^^^
  File "C:\Users\dilep\Desktop\deep\env\Lib\site-packages\django\db\backends\utils.py", line 122, in execute
    return super().execute(sql, params)
           ~~~~~~~~~~~~~~~^^^^^^^^^^^^^
  File "C:\Users\dilep\Desktop\deep\env\Lib\site-packages\django\db\backends\utils.py", line 79, in execute
    return self._execute_with_wrappers(
           ~~~~~~~~~~~~~~~~~~~~~~~~~~~^
        sql, params, many=False, executor=self._execute
        ^^^^^^^^^^^^^^^^^^^^^^^^^^^^^^^^^^^^^^^^^^^^^^^
    )
    ^
  File "C:\Users\dilep\Desktop\deep\env\Lib\site-packages\django\db\backends\utils.py", line 92, in _execute_with_wrappers
    return executor(sql, params, many, context)
  File "C:\Users\dilep\Desktop\deep\env\Lib\site-packages\django\db\backends\utils.py", line 100, in _execute
    with self.db.wrap_database_errors:
         ^^^^^^^^^^^^^^^^^^^^^^^^^^^^
  File "C:\Users\dilep\Desktop\deep\env\Lib\site-packages\django\db\utils.py", line 91, in __exit__
    raise dj_exc_value.with_traceback(traceback) from exc_value
  File "C:\Users\dilep\Desktop\deep\env\Lib\site-packages\django\db\backends\utils.py", line 105, in _execute
    return self.cursor.execute(sql, params)
           ~~~~~~~~~~~~~~~~~~~^^^^^^^^^^^^^
  File "C:\Users\dilep\Desktop\deep\env\Lib\site-packages\django\db\backends\mysql\base.py", line 76, in execute
    return self.cursor.execute(query, args)
           ~~~~~~~~~~~~~~~~~~~^^^^^^^^^^^^^
  File "C:\Users\dilep\Desktop\deep\env\Lib\site-packages\MySQLdb\cursors.py", line 179, in execute
    res = self._query(mogrified_query)
  File "C:\Users\dilep\Desktop\deep\env\Lib\site-packages\MySQLdb\cursors.py", line 330, in _query
    db.query(q)
    ~~~~~~~~^^^
  File "C:\Users\dilep\Desktop\deep\env\Lib\site-packages\MySQLdb\connections.py", line 280, in query
    _mysql.connection.query(self, query)
    ~~~~~~~~~~~~~~~~~~~~~~~^^^^^^^^^^^^^
django.db.utils.OperationalError: (1054, "Unknown column 'wasteapp_userprofile.credits' in 'field list'")
"GET /admin/wasteapp/userprofile/ HTTP/1.1" 500 201932
Internal Server Error: /admin/wasteapp/userprofile/
Traceback (most recent call last):
  File "C:\Users\dilep\Desktop\deep\env\Lib\site-packages\django\db\backends\utils.py", line 105, in _execute
    return self.cursor.execute(sql, params)
           ~~~~~~~~~~~~~~~~~~~^^^^^^^^^^^^^
  File "C:\Users\dilep\Desktop\deep\env\Lib\site-packages\django\db\backends\mysql\base.py", line 76, in execute
    return self.cursor.execute(query, args)
           ~~~~~~~~~~~~~~~~~~~^^^^^^^^^^^^^
  File "C:\Users\dilep\Desktop\deep\env\Lib\site-packages\MySQLdb\cursors.py", line 179, in execute
    res = self._query(mogrified_query)
  File "C:\Users\dilep\Desktop\deep\env\Lib\site-packages\MySQLdb\cursors.py", line 330, in _query
    db.query(q)
    ~~~~~~~~^^^
  File "C:\Users\dilep\Desktop\deep\env\Lib\site-packages\MySQLdb\connections.py", line 280, in query
    _mysql.connection.query(self, query)
    ~~~~~~~~~~~~~~~~~~~~~~~^^^^^^^^^^^^^
MySQLdb.OperationalError: (1054, "Unknown column 'wasteapp_userprofile.credits' in 'field list'")

The above exception was the direct cause of the following exception:

Traceback (most recent call last):
  File "C:\Users\dilep\Desktop\deep\env\Lib\site-packages\django\core\handlers\exception.py", line 55, in inner
    response = get_response(request)
  File "C:\Users\dilep\Desktop\deep\env\Lib\site-packages\django\core\handlers\base.py", line 197, in _get_response
    response = wrapped_callback(request, *callback_args, **callback_kwargs)
  File "C:\Users\dilep\Desktop\deep\env\Lib\site-packages\django\contrib\admin\options.py", line 718, in wrapper
    return self.admin_site.admin_view(view)(*args, **kwargs)
           ~~~~~~~~~~~~~~~~~~~~~~~~~~~~~~~~^^^^^^^^^^^^^^^^^
  File "C:\Users\dilep\Desktop\deep\env\Lib\site-packages\django\utils\decorators.py", line 188, in _view_wrapper
    result = _process_exception(request, e)
  File "C:\Users\dilep\Desktop\deep\env\Lib\site-packages\django\utils\decorators.py", line 186, in _view_wrapper
    response = view_func(request, *args, **kwargs)
  File "C:\Users\dilep\Desktop\deep\env\Lib\site-packages\django\views\decorators\cache.py", line 80, in _view_wrapper
    response = view_func(request, *args, **kwargs)
  File "C:\Users\dilep\Desktop\deep\env\Lib\site-packages\django\contrib\admin\sites.py", line 241, in inner
    return view(request, *args, **kwargs)
  File "C:\Users\dilep\Desktop\deep\env\Lib\site-packages\django\utils\decorators.py", line 48, in _wrapper
    return bound_method(*args, **kwargs)
  File "C:\Users\dilep\Desktop\deep\env\Lib\site-packages\django\utils\decorators.py", line 188, in _view_wrapper
    result = _process_exception(request, e)
  File "C:\Users\dilep\Desktop\deep\env\Lib\site-packages\django\utils\decorators.py", line 186, in _view_wrapper
    response = view_func(request, *args, **kwargs)
  File "C:\Users\dilep\Desktop\deep\env\Lib\site-packages\django\contrib\admin\options.py", line 2138, in changelist_view
    "selection_note": _("0 of %(cnt)s selected") % {"cnt": len(cl.result_list)},
                                                           ~~~^^^^^^^^^^^^^^^^
  File "C:\Users\dilep\Desktop\deep\env\Lib\site-packages\django\db\models\query.py", line 382, in __len__
    self._fetch_all()
    ~~~~~~~~~~~~~~~^^
  File "C:\Users\dilep\Desktop\deep\env\Lib\site-packages\django\db\models\query.py", line 1928, in _fetch_all
    self._result_cache = list(self._iterable_class(self))
                         ~~~~^^^^^^^^^^^^^^^^^^^^^^^^^^^^
  File "C:\Users\dilep\Desktop\deep\env\Lib\site-packages\django\db\models\query.py", line 91, in __iter__
    results = compiler.execute_sql(
        chunked_fetch=self.chunked_fetch, chunk_size=self.chunk_size
    )
  File "C:\Users\dilep\Desktop\deep\env\Lib\site-packages\django\db\models\sql\compiler.py", line 1574, in execute_sql
    cursor.execute(sql, params)
    ~~~~~~~~~~~~~~^^^^^^^^^^^^^
  File "C:\Users\dilep\Desktop\deep\env\Lib\site-packages\django\db\backends\utils.py", line 122, in execute
    return super().execute(sql, params)
           ~~~~~~~~~~~~~~~^^^^^^^^^^^^^
  File "C:\Users\dilep\Desktop\deep\env\Lib\site-packages\django\db\backends\utils.py", line 79, in execute
    return self._execute_with_wrappers(
           ~~~~~~~~~~~~~~~~~~~~~~~~~~~^
        sql, params, many=False, executor=self._execute
        ^^^^^^^^^^^^^^^^^^^^^^^^^^^^^^^^^^^^^^^^^^^^^^^
    )
    ^
  File "C:\Users\dilep\Desktop\deep\env\Lib\site-packages\django\db\backends\utils.py", line 92, in _execute_with_wrappers
    return executor(sql, params, many, context)
  File "C:\Users\dilep\Desktop\deep\env\Lib\site-packages\django\db\backends\utils.py", line 100, in _execute
    with self.db.wrap_database_errors:
         ^^^^^^^^^^^^^^^^^^^^^^^^^^^^
  File "C:\Users\dilep\Desktop\deep\env\Lib\site-packages\django\db\utils.py", line 91, in __exit__
    raise dj_exc_value.with_traceback(traceback) from exc_value
  File "C:\Users\dilep\Desktop\deep\env\Lib\site-packages\django\db\backends\utils.py", line 105, in _execute
    return self.cursor.execute(sql, params)
           ~~~~~~~~~~~~~~~~~~~^^^^^^^^^^^^^
  File "C:\Users\dilep\Desktop\deep\env\Lib\site-packages\django\db\backends\mysql\base.py", line 76, in execute
    return self.cursor.execute(query, args)
           ~~~~~~~~~~~~~~~~~~~^^^^^^^^^^^^^
  File "C:\Users\dilep\Desktop\deep\env\Lib\site-packages\MySQLdb\cursors.py", line 179, in execute
    res = self._query(mogrified_query)
  File "C:\Users\dilep\Desktop\deep\env\Lib\site-packages\MySQLdb\cursors.py", line 330, in _query
    db.query(q)
    ~~~~~~~~^^^
  File "C:\Users\dilep\Desktop\deep\env\Lib\site-packages\MySQLdb\connections.py", line 280, in query
    _mysql.connection.query(self, query)
    ~~~~~~~~~~~~~~~~~~~~~~~^^^^^^^^^^^^^
django.db.utils.OperationalError: (1054, "Unknown column 'wasteapp_userprofile.credits' in 'field list'")
"GET /admin/wasteapp/userprofile/ HTTP/1.1" 500 201931
Internal Server Error: /
Traceback (most recent call last):
  File "C:\Users\dilep\Desktop\deep\env\Lib\site-packages\django\db\models\fields\related_descriptors.py", line 512, in __get__
    rel_obj = self.related.get_cached_value(instance)
  File "C:\Users\dilep\Desktop\deep\env\Lib\site-packages\django\db\models\fields\mixins.py", line 37, in get_cached_value
    return instance._state.fields_cache[self.cache_name]
           ~~~~~~~~~~~~~~~~~~~~~~~~~~~~^^^^^^^^^^^^^^^^^
KeyError: 'userprofile'

During handling of the above exception, another exception occurred:

Traceback (most recent call last):
  File "C:\Users\dilep\Desktop\deep\env\Lib\site-packages\django\db\backends\utils.py", line 105, in _execute
    return self.cursor.execute(sql, params)
           ~~~~~~~~~~~~~~~~~~~^^^^^^^^^^^^^
  File "C:\Users\dilep\Desktop\deep\env\Lib\site-packages\django\db\backends\mysql\base.py", line 76, in execute
    return self.cursor.execute(query, args)
           ~~~~~~~~~~~~~~~~~~~^^^^^^^^^^^^^
  File "C:\Users\dilep\Desktop\deep\env\Lib\site-packages\MySQLdb\cursors.py", line 179, in execute
    res = self._query(mogrified_query)
  File "C:\Users\dilep\Desktop\deep\env\Lib\site-packages\MySQLdb\cursors.py", line 330, in _query
    db.query(q)
    ~~~~~~~~^^^
  File "C:\Users\dilep\Desktop\deep\env\Lib\site-packages\MySQLdb\connections.py", line 280, in query
    _mysql.connection.query(self, query)
    ~~~~~~~~~~~~~~~~~~~~~~~^^^^^^^^^^^^^
MySQLdb.OperationalError: (1054, "Unknown column 'wasteapp_userprofile.credits' in 'field list'")

The above exception was the direct cause of the following exception:

Traceback (most recent call last):
  File "C:\Users\dilep\Desktop\deep\env\Lib\site-packages\django\core\handlers\exception.py", line 55, in inner
    response = get_response(request)
  File "C:\Users\dilep\Desktop\deep\env\Lib\site-packages\django\core\handlers\base.py", line 197, in _get_response
    response = wrapped_callback(request, *callback_args, **callback_kwargs)
  File "C:\Users\dilep\Desktop\deep\wasteapp\views.py", line 64, in user_login
    login(request, user)
    ~~~~~^^^^^^^^^^^^^^^
  File "C:\Users\dilep\Desktop\deep\env\Lib\site-packages\django\contrib\auth\__init__.py", line 152, in login
    user_logged_in.send(sender=user.__class__, request=request, user=user)
    ~~~~~~~~~~~~~~~~~~~^^^^^^^^^^^^^^^^^^^^^^^^^^^^^^^^^^^^^^^^^^^^^^^^^^^
  File "C:\Users\dilep\Desktop\deep\env\Lib\site-packages\django\dispatch\dispatcher.py", line 189, in send
    response = receiver(signal=self, sender=sender, **named)
  File "C:\Users\dilep\Desktop\deep\env\Lib\site-packages\django\contrib\auth\models.py", line 24, in update_last_login
    user.save(update_fields=["last_login"])
    ~~~~~~~~~^^^^^^^^^^^^^^^^^^^^^^^^^^^^^^
  File "C:\Users\dilep\Desktop\deep\env\Lib\site-packages\django\contrib\auth\base_user.py", line 62, in save
    super().save(*args, **kwargs)
    ~~~~~~~~~~~~^^^^^^^^^^^^^^^^^
  File "C:\Users\dilep\Desktop\deep\env\Lib\site-packages\django\db\models\base.py", line 892, in save
    self.save_base(
    ~~~~~~~~~~~~~~^
        using=using,
        ^^^^^^^^^^^^
    ...<2 lines>...
        update_fields=update_fields,
        ^^^^^^^^^^^^^^^^^^^^^^^^^^^^
    )
    ^
  File "C:\Users\dilep\Desktop\deep\env\Lib\site-packages\django\db\models\base.py", line 1013, in save_base
    post_save.send(
    ~~~~~~~~~~~~~~^
        sender=origin,
        ^^^^^^^^^^^^^^
    ...<4 lines>...
        using=using,
        ^^^^^^^^^^^^
    )
    ^
  File "C:\Users\dilep\Desktop\deep\env\Lib\site-packages\django\dispatch\dispatcher.py", line 189, in send
    response = receiver(signal=self, sender=sender, **named)
  File "C:\Users\dilep\Desktop\deep\wasteapp\models.py", line 22, in save_user_profile
    instance.userprofile.save()
    ^^^^^^^^^^^^^^^^^^^^
  File "C:\Users\dilep\Desktop\deep\env\Lib\site-packages\django\db\models\fields\related_descriptors.py", line 520, in __get__
    rel_obj = self.get_queryset(instance=instance).get(**filter_args)
  File "C:\Users\dilep\Desktop\deep\env\Lib\site-packages\django\db\models\query.py", line 645, in get
    num = len(clone)
  File "C:\Users\dilep\Desktop\deep\env\Lib\site-packages\django\db\models\query.py", line 382, in __len__
    self._fetch_all()
    ~~~~~~~~~~~~~~~^^
  File "C:\Users\dilep\Desktop\deep\env\Lib\site-packages\django\db\models\query.py", line 1928, in _fetch_all
    self._result_cache = list(self._iterable_class(self))
                         ~~~~^^^^^^^^^^^^^^^^^^^^^^^^^^^^
  File "C:\Users\dilep\Desktop\deep\env\Lib\site-packages\django\db\models\query.py", line 91, in __iter__
    results = compiler.execute_sql(
        chunked_fetch=self.chunked_fetch, chunk_size=self.chunk_size
    )
  File "C:\Users\dilep\Desktop\deep\env\Lib\site-packages\django\db\models\sql\compiler.py", line 1574, in execute_sql
    cursor.execute(sql, params)
    ~~~~~~~~~~~~~~^^^^^^^^^^^^^
  File "C:\Users\dilep\Desktop\deep\env\Lib\site-packages\django\db\backends\utils.py", line 122, in execute
    return super().execute(sql, params)
           ~~~~~~~~~~~~~~~^^^^^^^^^^^^^
  File "C:\Users\dilep\Desktop\deep\env\Lib\site-packages\django\db\backends\utils.py", line 79, in execute
    return self._execute_with_wrappers(
           ~~~~~~~~~~~~~~~~~~~~~~~~~~~^
        sql, params, many=False, executor=self._execute
        ^^^^^^^^^^^^^^^^^^^^^^^^^^^^^^^^^^^^^^^^^^^^^^^
    )
    ^
  File "C:\Users\dilep\Desktop\deep\env\Lib\site-packages\django\db\backends\utils.py", line 92, in _execute_with_wrappers
    return executor(sql, params, many, context)
  File "C:\Users\dilep\Desktop\deep\env\Lib\site-packages\django\db\backends\utils.py", line 100, in _execute
    with self.db.wrap_database_errors:
         ^^^^^^^^^^^^^^^^^^^^^^^^^^^^
  File "C:\Users\dilep\Desktop\deep\env\Lib\site-packages\django\db\utils.py", line 91, in __exit__
    raise dj_exc_value.with_traceback(traceback) from exc_value
  File "C:\Users\dilep\Desktop\deep\env\Lib\site-packages\django\db\backends\utils.py", line 105, in _execute
    return self.cursor.execute(sql, params)
           ~~~~~~~~~~~~~~~~~~~^^^^^^^^^^^^^
  File "C:\Users\dilep\Desktop\deep\env\Lib\site-packages\django\db\backends\mysql\base.py", line 76, in execute
    return self.cursor.execute(query, args)
           ~~~~~~~~~~~~~~~~~~~^^^^^^^^^^^^^
  File "C:\Users\dilep\Desktop\deep\env\Lib\site-packages\MySQLdb\cursors.py", line 179, in execute
    res = self._query(mogrified_query)
  File "C:\Users\dilep\Desktop\deep\env\Lib\site-packages\MySQLdb\cursors.py", line 330, in _query
    db.query(q)
    ~~~~~~~~^^^
  File "C:\Users\dilep\Desktop\deep\env\Lib\site-packages\MySQLdb\connections.py", line 280, in query
    _mysql.connection.query(self, query)
    ~~~~~~~~~~~~~~~~~~~~~~~^^^^^^^^^^^^^
django.db.utils.OperationalError: (1054, "Unknown column 'wasteapp_userprofile.credits' in 'field list'")
"POST / HTTP/1.1" 500 216020
Internal Server Error: /dashboard/
Traceback (most recent call last):
  File "C:\Users\dilep\Desktop\deep\env\Lib\site-packages\django\db\backends\utils.py", line 105, in _execute
    return self.cursor.execute(sql, params)
           ~~~~~~~~~~~~~~~~~~~^^^^^^^^^^^^^
  File "C:\Users\dilep\Desktop\deep\env\Lib\site-packages\django\db\backends\mysql\base.py", line 76, in execute
    return self.cursor.execute(query, args)
           ~~~~~~~~~~~~~~~~~~~^^^^^^^^^^^^^
  File "C:\Users\dilep\Desktop\deep\env\Lib\site-packages\MySQLdb\cursors.py", line 179, in execute
    res = self._query(mogrified_query)
  File "C:\Users\dilep\Desktop\deep\env\Lib\site-packages\MySQLdb\cursors.py", line 330, in _query
    db.query(q)
    ~~~~~~~~^^^
  File "C:\Users\dilep\Desktop\deep\env\Lib\site-packages\MySQLdb\connections.py", line 280, in query
    _mysql.connection.query(self, query)
    ~~~~~~~~~~~~~~~~~~~~~~~^^^^^^^^^^^^^
MySQLdb.OperationalError: (1054, "Unknown column 'wasteapp_wastedisposalrecord.ir_sensor' in 'field list'")

The above exception was the direct cause of the following exception:

Traceback (most recent call last):
  File "C:\Users\dilep\Desktop\deep\env\Lib\site-packages\django\core\handlers\exception.py", line 55, in inner
    response = get_response(request)
  File "C:\Users\dilep\Desktop\deep\env\Lib\site-packages\django\core\handlers\base.py", line 197, in _get_response
    response = wrapped_callback(request, *callback_args, **callback_kwargs)
  File "C:\Users\dilep\Desktop\deep\env\Lib\site-packages\django\contrib\auth\decorators.py", line 60, in _view_wrapper
    return view_func(request, *args, **kwargs)
  File "C:\Users\dilep\Desktop\deep\wasteapp\views.py", line 89, in dashboard
    return render(request, 'wasteapp/dashboard.html', context)
  File "C:\Users\dilep\Desktop\deep\env\Lib\site-packages\django\shortcuts.py", line 25, in render
    content = loader.render_to_string(template_name, context, request, using=using)
  File "C:\Users\dilep\Desktop\deep\env\Lib\site-packages\django\template\loader.py", line 62, in render_to_string
    return template.render(context, request)
           ~~~~~~~~~~~~~~~^^^^^^^^^^^^^^^^^^
  File "C:\Users\dilep\Desktop\deep\env\Lib\site-packages\django\template\backends\django.py", line 107, in render
    return self.template.render(context)
           ~~~~~~~~~~~~~~~~~~~~^^^^^^^^^
  File "C:\Users\dilep\Desktop\deep\env\Lib\site-packages\django\template\base.py", line 171, in render
    return self._render(context)
           ~~~~~~~~~~~~^^^^^^^^^
  File "C:\Users\dilep\Desktop\deep\env\Lib\site-packages\django\template\base.py", line 163, in _render
    return self.nodelist.render(context)
           ~~~~~~~~~~~~~~~~~~~~^^^^^^^^^
  File "C:\Users\dilep\Desktop\deep\env\Lib\site-packages\django\template\base.py", line 1008, in render
    return SafeString("".join([node.render_annotated(context) for node in self]))
                               ~~~~~~~~~~~~~~~~~~~~~^^^^^^^^^
  File "C:\Users\dilep\Desktop\deep\env\Lib\site-packages\django\template\base.py", line 969, in render_annotated
    return self.render(context)
           ~~~~~~~~~~~^^^^^^^^^
  File "C:\Users\dilep\Desktop\deep\env\Lib\site-packages\django\template\defaulttags.py", line 199, in render
    len_values = len(values)
  File "C:\Users\dilep\Desktop\deep\env\Lib\site-packages\django\db\models\query.py", line 382, in __len__
    self._fetch_all()
    ~~~~~~~~~~~~~~~^^
  File "C:\Users\dilep\Desktop\deep\env\Lib\site-packages\django\db\models\query.py", line 1928, in _fetch_all
    self._result_cache = list(self._iterable_class(self))
                         ~~~~^^^^^^^^^^^^^^^^^^^^^^^^^^^^
  File "C:\Users\dilep\Desktop\deep\env\Lib\site-packages\django\db\models\query.py", line 91, in __iter__
    results = compiler.execute_sql(
        chunked_fetch=self.chunked_fetch, chunk_size=self.chunk_size
    )
  File "C:\Users\dilep\Desktop\deep\env\Lib\site-packages\django\db\models\sql\compiler.py", line 1574, in execute_sql
    cursor.execute(sql, params)
    ~~~~~~~~~~~~~~^^^^^^^^^^^^^
  File "C:\Users\dilep\Desktop\deep\env\Lib\site-packages\django\db\backends\utils.py", line 122, in execute
    return super().execute(sql, params)
           ~~~~~~~~~~~~~~~^^^^^^^^^^^^^
  File "C:\Users\dilep\Desktop\deep\env\Lib\site-packages\django\db\backends\utils.py", line 79, in execute
    return self._execute_with_wrappers(
           ~~~~~~~~~~~~~~~~~~~~~~~~~~~^
        sql, params, many=False, executor=self._execute
        ^^^^^^^^^^^^^^^^^^^^^^^^^^^^^^^^^^^^^^^^^^^^^^^
    )
    ^
  File "C:\Users\dilep\Desktop\deep\env\Lib\site-packages\django\db\backends\utils.py", line 92, in _execute_with_wrappers
    return executor(sql, params, many, context)
  File "C:\Users\dilep\Desktop\deep\env\Lib\site-packages\django\db\backends\utils.py", line 100, in _execute
    with self.db.wrap_database_errors:
         ^^^^^^^^^^^^^^^^^^^^^^^^^^^^
  File "C:\Users\dilep\Desktop\deep\env\Lib\site-packages\django\db\utils.py", line 91, in __exit__
    raise dj_exc_value.with_traceback(traceback) from exc_value
  File "C:\Users\dilep\Desktop\deep\env\Lib\site-packages\django\db\backends\utils.py", line 105, in _execute
    return self.cursor.execute(sql, params)
           ~~~~~~~~~~~~~~~~~~~^^^^^^^^^^^^^
  File "C:\Users\dilep\Desktop\deep\env\Lib\site-packages\django\db\backends\mysql\base.py", line 76, in execute
    return self.cursor.execute(query, args)
           ~~~~~~~~~~~~~~~~~~~^^^^^^^^^^^^^
  File "C:\Users\dilep\Desktop\deep\env\Lib\site-packages\MySQLdb\cursors.py", line 179, in execute
    res = self._query(mogrified_query)
  File "C:\Users\dilep\Desktop\deep\env\Lib\site-packages\MySQLdb\cursors.py", line 330, in _query
    db.query(q)
    ~~~~~~~~^^^
  File "C:\Users\dilep\Desktop\deep\env\Lib\site-packages\MySQLdb\connections.py", line 280, in query
    _mysql.connection.query(self, query)
    ~~~~~~~~~~~~~~~~~~~~~~~^^^^^^^^^^^^^
django.db.utils.OperationalError: (1054, "Unknown column 'wasteapp_wastedisposalrecord.ir_sensor' in 'field list'")
"GET /dashboard/ HTTP/1.1" 500 211854
Internal Server Error: /record/
Traceback (most recent call last):
  File "C:\Users\dilep\Desktop\deep\env\Lib\site-packages\django\db\backends\utils.py", line 105, in _execute
    return self.cursor.execute(sql, params)
           ~~~~~~~~~~~~~~~~~~~^^^^^^^^^^^^^
  File "C:\Users\dilep\Desktop\deep\env\Lib\site-packages\django\db\backends\mysql\base.py", line 76, in execute
    return self.cursor.execute(query, args)
           ~~~~~~~~~~~~~~~~~~~^^^^^^^^^^^^^
  File "C:\Users\dilep\Desktop\deep\env\Lib\site-packages\MySQLdb\cursors.py", line 179, in execute
    res = self._query(mogrified_query)
  File "C:\Users\dilep\Desktop\deep\env\Lib\site-packages\MySQLdb\cursors.py", line 330, in _query
    db.query(q)
    ~~~~~~~~^^^
  File "C:\Users\dilep\Desktop\deep\env\Lib\site-packages\MySQLdb\connections.py", line 280, in query
    _mysql.connection.query(self, query)
    ~~~~~~~~~~~~~~~~~~~~~~~^^^^^^^^^^^^^
MySQLdb.IntegrityError: (1364, "Field 'ir_sensor' doesn't have a default value")

The above exception was the direct cause of the following exception:

Traceback (most recent call last):
  File "C:\Users\dilep\Desktop\deep\env\Lib\site-packages\django\core\handlers\exception.py", line 55, in inner
    response = get_response(request)
  File "C:\Users\dilep\Desktop\deep\env\Lib\site-packages\django\core\handlers\base.py", line 197, in _get_response
    response = wrapped_callback(request, *callback_args, **callback_kwargs)
  File "C:\Users\dilep\Desktop\deep\env\Lib\site-packages\django\contrib\auth\decorators.py", line 60, in _view_wrapper
    return view_func(request, *args, **kwargs)
  File "C:\Users\dilep\Desktop\deep\wasteapp\views.py", line 143, in record_waste
    waste_disposal.save()
    ~~~~~~~~~~~~~~~~~~~^^
  File "C:\Users\dilep\Desktop\deep\wasteapp\models.py", line 39, in save
    super().save(*args, **kwargs)
    ~~~~~~~~~~~~^^^^^^^^^^^^^^^^^
  File "C:\Users\dilep\Desktop\deep\env\Lib\site-packages\django\db\models\base.py", line 892, in save
    self.save_base(
    ~~~~~~~~~~~~~~^
        using=using,
        ^^^^^^^^^^^^
    ...<2 lines>...
        update_fields=update_fields,
        ^^^^^^^^^^^^^^^^^^^^^^^^^^^^
    )
    ^
  File "C:\Users\dilep\Desktop\deep\env\Lib\site-packages\django\db\models\base.py", line 998, in save_base
    updated = self._save_table(
        raw,
    ...<4 lines>...
        update_fields,
    )
  File "C:\Users\dilep\Desktop\deep\env\Lib\site-packages\django\db\models\base.py", line 1161, in _save_table
    results = self._do_insert(
        cls._base_manager, using, fields, returning_fields, raw
    )
  File "C:\Users\dilep\Desktop\deep\env\Lib\site-packages\django\db\models\base.py", line 1202, in _do_insert
    return manager._insert(
           ~~~~~~~~~~~~~~~^
        [self],
        ^^^^^^^
    ...<3 lines>...
        raw=raw,
        ^^^^^^^^
    )
    ^
  File "C:\Users\dilep\Desktop\deep\env\Lib\site-packages\django\db\models\manager.py", line 87, in manager_method
    return getattr(self.get_queryset(), name)(*args, **kwargs)
           ~~~~~~~~~~~~~~~~~~~~~~~~~~~~~~~~~~^^^^^^^^^^^^^^^^^
  File "C:\Users\dilep\Desktop\deep\env\Lib\site-packages\django\db\models\query.py", line 1847, in _insert
    return query.get_compiler(using=using).execute_sql(returning_fields)
           ~~~~~~~~~~~~~~~~~~~~~~~~~~~~~~~~~~~~~~~~~~~^^^^^^^^^^^^^^^^^^
  File "C:\Users\dilep\Desktop\deep\env\Lib\site-packages\django\db\models\sql\compiler.py", line 1836, in execute_sql
    cursor.execute(sql, params)
    ~~~~~~~~~~~~~~^^^^^^^^^^^^^
  File "C:\Users\dilep\Desktop\deep\env\Lib\site-packages\django\db\backends\utils.py", line 122, in execute
    return super().execute(sql, params)
           ~~~~~~~~~~~~~~~^^^^^^^^^^^^^
  File "C:\Users\dilep\Desktop\deep\env\Lib\site-packages\django\db\backends\utils.py", line 79, in execute
    return self._execute_with_wrappers(
           ~~~~~~~~~~~~~~~~~~~~~~~~~~~^
        sql, params, many=False, executor=self._execute
        ^^^^^^^^^^^^^^^^^^^^^^^^^^^^^^^^^^^^^^^^^^^^^^^
    )
    ^
  File "C:\Users\dilep\Desktop\deep\env\Lib\site-packages\django\db\backends\utils.py", line 92, in _execute_with_wrappers
    return executor(sql, params, many, context)
  File "C:\Users\dilep\Desktop\deep\env\Lib\site-packages\django\db\backends\utils.py", line 100, in _execute
    with self.db.wrap_database_errors:
         ^^^^^^^^^^^^^^^^^^^^^^^^^^^^
  File "C:\Users\dilep\Desktop\deep\env\Lib\site-packages\django\db\utils.py", line 91, in __exit__
    raise dj_exc_value.with_traceback(traceback) from exc_value
  File "C:\Users\dilep\Desktop\deep\env\Lib\site-packages\django\db\backends\utils.py", line 105, in _execute
    return self.cursor.execute(sql, params)
           ~~~~~~~~~~~~~~~~~~~^^^^^^^^^^^^^
  File "C:\Users\dilep\Desktop\deep\env\Lib\site-packages\django\db\backends\mysql\base.py", line 76, in execute
    return self.cursor.execute(query, args)
           ~~~~~~~~~~~~~~~~~~~^^^^^^^^^^^^^
  File "C:\Users\dilep\Desktop\deep\env\Lib\site-packages\MySQLdb\cursors.py", line 179, in execute
    res = self._query(mogrified_query)
  File "C:\Users\dilep\Desktop\deep\env\Lib\site-packages\MySQLdb\cursors.py", line 330, in _query
    db.query(q)
    ~~~~~~~~^^^
  File "C:\Users\dilep\Desktop\deep\env\Lib\site-packages\MySQLdb\connections.py", line 280, in query
    _mysql.connection.query(self, query)
    ~~~~~~~~~~~~~~~~~~~~~~~^^^^^^^^^^^^^
django.db.utils.IntegrityError: (1364, "Field 'ir_sensor' doesn't have a default value")
"POST /record/ HTTP/1.1" 500 192961
Internal Server Error: /record/
Traceback (most recent call last):
  File "C:\Users\dilep\Desktop\deep\env\Lib\site-packages\django\db\backends\utils.py", line 105, in _execute
    return self.cursor.execute(sql, params)
           ~~~~~~~~~~~~~~~~~~~^^^^^^^^^^^^^
  File "C:\Users\dilep\Desktop\deep\env\Lib\site-packages\django\db\backends\mysql\base.py", line 76, in execute
    return self.cursor.execute(query, args)
           ~~~~~~~~~~~~~~~~~~~^^^^^^^^^^^^^
  File "C:\Users\dilep\Desktop\deep\env\Lib\site-packages\MySQLdb\cursors.py", line 179, in execute
    res = self._query(mogrified_query)
  File "C:\Users\dilep\Desktop\deep\env\Lib\site-packages\MySQLdb\cursors.py", line 330, in _query
    db.query(q)
    ~~~~~~~~^^^
  File "C:\Users\dilep\Desktop\deep\env\Lib\site-packages\MySQLdb\connections.py", line 280, in query
    _mysql.connection.query(self, query)
    ~~~~~~~~~~~~~~~~~~~~~~~^^^^^^^^^^^^^
MySQLdb.IntegrityError: (1364, "Field 'ir_sensor' doesn't have a default value")

The above exception was the direct cause of the following exception:

Traceback (most recent call last):
  File "C:\Users\dilep\Desktop\deep\env\Lib\site-packages\django\core\handlers\exception.py", line 55, in inner
    response = get_response(request)
  File "C:\Users\dilep\Desktop\deep\env\Lib\site-packages\django\core\handlers\base.py", line 197, in _get_response
    response = wrapped_callback(request, *callback_args, **callback_kwargs)
  File "C:\Users\dilep\Desktop\deep\env\Lib\site-packages\django\contrib\auth\decorators.py", line 60, in _view_wrapper
    return view_func(request, *args, **kwargs)
  File "C:\Users\dilep\Desktop\deep\wasteapp\views.py", line 143, in record_waste
    waste_disposal.save()
    ~~~~~~~~~~~~~~~~~~~^^
  File "C:\Users\dilep\Desktop\deep\wasteapp\models.py", line 41, in save
    super().save(*args, **kwargs)
    ~~~~~~~~~~~~^^^^^^^^^^^^^^^^^
  File "C:\Users\dilep\Desktop\deep\env\Lib\site-packages\django\db\models\base.py", line 892, in save
    self.save_base(
    ~~~~~~~~~~~~~~^
        using=using,
        ^^^^^^^^^^^^
    ...<2 lines>...
        update_fields=update_fields,
        ^^^^^^^^^^^^^^^^^^^^^^^^^^^^
    )
    ^
  File "C:\Users\dilep\Desktop\deep\env\Lib\site-packages\django\db\models\base.py", line 998, in save_base
    updated = self._save_table(
        raw,
    ...<4 lines>...
        update_fields,
    )
  File "C:\Users\dilep\Desktop\deep\env\Lib\site-packages\django\db\models\base.py", line 1161, in _save_table
    results = self._do_insert(
        cls._base_manager, using, fields, returning_fields, raw
    )
  File "C:\Users\dilep\Desktop\deep\env\Lib\site-packages\django\db\models\base.py", line 1202, in _do_insert
    return manager._insert(
           ~~~~~~~~~~~~~~~^
        [self],
        ^^^^^^^
    ...<3 lines>...
        raw=raw,
        ^^^^^^^^
    )
    ^
  File "C:\Users\dilep\Desktop\deep\env\Lib\site-packages\django\db\models\manager.py", line 87, in manager_method
    return getattr(self.get_queryset(), name)(*args, **kwargs)
           ~~~~~~~~~~~~~~~~~~~~~~~~~~~~~~~~~~^^^^^^^^^^^^^^^^^
  File "C:\Users\dilep\Desktop\deep\env\Lib\site-packages\django\db\models\query.py", line 1847, in _insert
    return query.get_compiler(using=using).execute_sql(returning_fields)
           ~~~~~~~~~~~~~~~~~~~~~~~~~~~~~~~~~~~~~~~~~~~^^^^^^^^^^^^^^^^^^
  File "C:\Users\dilep\Desktop\deep\env\Lib\site-packages\django\db\models\sql\compiler.py", line 1836, in execute_sql
    cursor.execute(sql, params)
    ~~~~~~~~~~~~~~^^^^^^^^^^^^^
  File "C:\Users\dilep\Desktop\deep\env\Lib\site-packages\django\db\backends\utils.py", line 122, in execute
    return super().execute(sql, params)
           ~~~~~~~~~~~~~~~^^^^^^^^^^^^^
  File "C:\Users\dilep\Desktop\deep\env\Lib\site-packages\django\db\backends\utils.py", line 79, in execute
    return self._execute_with_wrappers(
           ~~~~~~~~~~~~~~~~~~~~~~~~~~~^
        sql, params, many=False, executor=self._execute
        ^^^^^^^^^^^^^^^^^^^^^^^^^^^^^^^^^^^^^^^^^^^^^^^
    )
    ^
  File "C:\Users\dilep\Desktop\deep\env\Lib\site-packages\django\db\backends\utils.py", line 92, in _execute_with_wrappers
    return executor(sql, params, many, context)
  File "C:\Users\dilep\Desktop\deep\env\Lib\site-packages\django\db\backends\utils.py", line 100, in _execute
    with self.db.wrap_database_errors:
         ^^^^^^^^^^^^^^^^^^^^^^^^^^^^
  File "C:\Users\dilep\Desktop\deep\env\Lib\site-packages\django\db\utils.py", line 91, in __exit__
    raise dj_exc_value.with_traceback(traceback) from exc_value
  File "C:\Users\dilep\Desktop\deep\env\Lib\site-packages\django\db\backends\utils.py", line 105, in _execute
    return self.cursor.execute(sql, params)
           ~~~~~~~~~~~~~~~~~~~^^^^^^^^^^^^^
  File "C:\Users\dilep\Desktop\deep\env\Lib\site-packages\django\db\backends\mysql\base.py", line 76, in execute
    return self.cursor.execute(query, args)
           ~~~~~~~~~~~~~~~~~~~^^^^^^^^^^^^^
  File "C:\Users\dilep\Desktop\deep\env\Lib\site-packages\MySQLdb\cursors.py", line 179, in execute
    res = self._query(mogrified_query)
  File "C:\Users\dilep\Desktop\deep\env\Lib\site-packages\MySQLdb\cursors.py", line 330, in _query
    db.query(q)
    ~~~~~~~~^^^
  File "C:\Users\dilep\Desktop\deep\env\Lib\site-packages\MySQLdb\connections.py", line 280, in query
    _mysql.connection.query(self, query)
    ~~~~~~~~~~~~~~~~~~~~~~~^^^^^^^^^^^^^
django.db.utils.IntegrityError: (1364, "Field 'ir_sensor' doesn't have a default value")
"POST /record/ HTTP/1.1" 500 193166
